use failure::Fail;
use weresocool_error::Error;

fn main() {
    match run() {
        Ok(_) => {}
        e => {
            for cause in Fail::iter_causes(&e.unwrap_err()) {
                println!("Failure caused by: {}", cause);
            }
        }
    }
}

#[allow(unused_variables)]
fn run() -> Result<(), Error> {
    Ok(())
}

